Workbook
Name __xlnm._FilterDatabase: 'Annex A controls'!$A$2:$E$99
Name __xlnm._FilterDatabase_1: 'Annex A controls'!$A$2:$E$99
Name __xlnm.Print_Titles: 'Annex A controls'!$A$2:$IQ$2
Name Applicability: Metrics!$B$14:$B$16
Name CMM: #REF!
Name ControlTotal: 'Annex A controls'!$D$100
Name Excel_BuiltIn_Print_Area: 'Mandatory ISMS requirements'!$B$1:$E$60
Name Excel_BuiltIn_Print_Titles: 'Annex A controls'!$A$2:$IQ$2

Sheet Mandatory ISMS requirements
B1: Status of ISO/IEC 27001 implementation
B2: Sezione | C2: ISO/IEC 27001 requisiti | D2: Status | E2: Notes
B3: 4 | C3: Contesto dell'organizzazione
B4: 4.1 | C4: Contesto dell'organizzazione
B5: 4.1 | C5: Determinare gli obiettivi ISMS dell'organizzazione e tutti i problemi che potrebbero influenzare la sua efficacia | D5: Managed | E5: L'azienda ha deciso di valutare la rilevanza del cambiamento climatico per il proprio Sistema di Gestione, in ottemperanza alle nuove direttive emanate a febbraio 2024 e ha seguito un approccio strutturato per determinare la rilevanza del cambiamento climatico, basandosi sui seguenti passaggi: 2.1 Identificazione dei rischi e delle opportunità: •Aumento dei costi energetici dovuto all'incremento del prezzo delle fonti fossili. •Interruzioni della catena di approvvigionamento causate da eventi meteorologici estremi. •Crescente domanda da parte dei clienti di prodotti ecocompatibili. •Possibilità di sviluppare nuovi prodotti e servizi eco-sostenibili. Pertanto l'azienda ha analizzato il proprio consumo energetico storico e le proiezioni future dei costi energetici, ha valutato la frequenza e la gravità degli eventi meteorologici estremi nella sua regione, ha condotto un'indagine tra i clienti per comprendere le loro aspettative in materia di sostenibilità 3. Risultati della valutazione Il cambiamento climatico è stato ritenuto una questione rilevante per il Sistema di Gestione ISO dell’azienda per le seguenti ragioni: •L'impatto potenziale sui costi energetici e sulla catena di approvvigionamento potrebbe avere un impatto significativo sulla redditività e sulla continuità operativa dell'azienda. •Le normative ambientali e di sicurezza più rigorose potrebbero richiedere all’azienda di investire in tecnologie a basse emissioni di carbonio e di implementare pratiche più sostenibili. 4. Azioni intraprese •Ridurre le emissioni di gas serra relativi ai propri prodotti / servizi •Aumentare l'utilizzo di energie rinnovabili. {{iso27001_4_1}}
B6: 4.2 | C6: Parti interessate
B7: 4.2 (a) | C7: Identificare le parti interessate tra cui leggi, regolamenti, contratti, ecc. | D7: Managed | E7: Il cambiamento climatico può avere un impatto significativo sulle parti interessate dell’azienda in diversi modi: • Clienti: Il cambiamento climatico potrebbe portare a una maggiore richiesta di prodotti ecocompatibili da parte dei clienti, il che potrebbe aumentare le vendite dell’azienda. Tuttavia, potrebbe anche portare a un aumento dei costi di produzione, il che potrebbe ridurre i profitti dell'azienda. • Investitori: Gli investitori potrebbero essere più propensi a investire in aziende che sono impegnate nella lotta contro il cambiamento climatico. Tuttavia, potrebbero anche essere più restii a investire in aziende che sono vulnerabili agli impatti del cambiamento climatico. • Dipendenti: Il cambiamento climatico potrebbe portare a condizioni meteorologiche più estreme, che potrebbero mettere a rischio la sicurezza dei dipendenti. Inoltre, potrebbe portare a una diminuzione della domanda di prodotti / servizi dell’azienda il che potrebbe portare a licenziamenti. • Comunità locali: Il cambiamento climatico potrebbe portare a eventi meteorologici estremi, come inondazioni o siccità, che potrebbero danneggiare le proprietà e le infrastrutture delle comunità locali. Inoltre, potrebbe portare a una diminuzione della qualità dell'aria e dell'acqua, il che potrebbe avere un impatto negativo sulla salute delle persone. • Fornitori: Il cambiamento climatico potrebbe interrompere le catene di approvvigionamento dell’azienda, il che potrebbe portare a una carenza di materie prime e componenti. Inoltre, potrebbe aumentare i costi di trasporto, il che potrebbe ridurre i profitti dell'azienda. • Autorità pubbliche: Le autorità pubbliche potrebbero imporre nuove normative ambientali e di sicurezza più rigorose, il che potrebbe aumentare i costi dell'azienda. Inoltre, potrebbero sanzionare l'azienda se non rispetta le normative ambientali e di sicurezza {{iso27001_4_2}}
B8: 4.2 (b) | C8: Determinare i requisiti e gli obblighi relativi alla sicurezza delle informazion | D8: Managed | E8: Visto Elenco documentazione esterna (ISO 27001:2017, d.LGS 196/2003; gdpr 2016/679; d.LGS 231/2001; Linee Guida dell'OCSE sulla sicurezza dei sistemi e delle reti d'informazione; D.lgs 81/2008).
B9: 4.3 | C9: Ambito ISMS
B10: 4.3 | C10: Determinare e documentare l'ambito ISMS | D10: Managed | E10: {{iso27001_4_3}}
B11: 4.4 | C11: ISMS
B12: 4.4 | C12: Stabilire, implementare, mantenere e migliorare continuamente un ISMS secondo lo standard! | D12: Managed | E12: {{iso27001_4_4}}
B13: 5 | C13: Leadership
B14: 5.1 | C14: Leadership e impegno
B15: 5.1 | C15: Il top management deve dimostrare leadership e impegno nei confronti | D15: Managed | E15: {{iso27001_5_1}}
B16: 5.2 | C16: Polizza
B17: 5.2 | C17: Definire la politica di sicurezza dell'informazione | D17: Managed | E17: {{iso27001_5_2}}
B18: 5.3 | C18: Ruoli, responsabilità e autorità organizzative
B19: 5.3 | C19: Assegnare e comunicare i ruoli e le responsabilità della sicurezza delle informazioni | D19: Managed | E19: {{iso27001_5_3}}
B20: 6 | C20: Pianificazione
B21: 6.1 | C21: Azioni per affrontare rischi e opportunità
B22: 6.1.1 | C22: Progettare/pianificare l'ISMS per soddisfare i requisiti, affrontare rischi e opportunità | D22: Managed | E22: {{iso27001_6_1_1}}
B23: 6.1.2 | C23: Definire e applicare un processo di valutazione del rischio per la sicurezza delle informazioni | D23: Managed | E23: {{iso27001_6_1_2}}
B24: 6.1.3 | C24: Documentare e applicare un processo di trattamento del rischio di sicurezza delle informazioni | D24: Managed | E24: {{iso27001_6_1_3}}
B25: 6.2 | C25: Obiettivi e piani di sicurezza dell'informazione
B26: 6.2 | C26: Stabilire e documentare gli obiettivi e i piani di sicurezza delle informazioni | D26: Managed | E26: {{iso27001_6_2}}
B27: 6.3 | C27: Pianificazione dei cambiamenti
B28: 6.3 | C28: Le modifiche sostanziali all'ISMS sono effettuate in modo pianificato | D28: Managed | E28: {{iso27001_6_3}}
B29: 7 | C29: Supporto
B30: 7.1 | C30: Risorse
B31: 7.1 | C31: Determinare e assegnare le risorse necessarie per l'ISMS | D31: Managed | E31: {{iso27001_7_1}}
B32: 7.2 | C32: Competenze
B33: 7.2 | C33: Determinare, documentare e rendere disponibili le competenze necessari | D33: Managed | E33: {{iso27001_7_2}}
B34: 7.3 | C34: Consapevolezza
B35: 7.3 | C35: Stabilire un programma di sensibilizzazione sulla sicurezza | D35: Managed | E35: {{iso27001_7_3}}
B36: 7.4 | C36: Comunicazione
B37: 7.4 | C37: Determinare la necessità di comunicazioni interne ed esterne rilevanti per l'ISMS | D37: Managed | E37: {{iso27001_7_4}}
B38: 7.5 | C38: informazioni documentate
B39: 7.5.1 | C39: Fornire la documentazione richiesta dallo standard più quella richiesta dall'organizzazione | D39: Managed | E39: {{iso27001_7_5_1}}
B40: 7.5.2 | C40: Fornire titoli di documenti, autori ecc., formattarli in modo coerente e rivederli e approvarli | D40: Managed | E40: {{iso27001_7_5_2}}
...

Sheet Annex A controls
B1: Statement of Applicability and status of information security controls
B2: Section | C2: Information security control | D2: Status | E2: Notes
B3: A5 | C3: Organizational controls
B4: A.5.1 | C4: Politiche per la sicurezza delle informazioni | D4: Managed | E4: Definita politica ed istruzioni sulla gestione della sicurezza delle informazioni
B5: A.5.2 | C5: Riesame delle Politiche per la sicurezza delle informazioni | D5: Managed | E5: Definiti ruoli e responsabilità aziendali per la sicurezza delle informazioni. Essendo azienda unipersonale, non è stato elaborato organigramma. Tuttavia sono state definite le responsabilità a livello di Procedure e Istruzioni Operative
B6: A.5.3 | C6: Segregazione dei compiti e le aree di responsabilità in conflitto. | D6: Managed | E6: Ruoli e responsabilità aziendali sono state definite per la sicurezza delle informazioni e la gestione di password e accessi.
B7: A.5.4 | C7: Richiesta della direzione al personale ad applicare la sicurezza delle informazioni in conformità con la politica di sicurezza delle informazioni stabilita | D7: Managed | E7: Le politiche sono riesaminate in occasione del riesame della direzione
B8: A.5.5 | C8: Stabilire e mantenere i contatti con le autorità competenti | D8: Managed | E8: I rapporti con le autorità sono mantenuti dalla stessa Direzione.
B9: A.5.6 | C9: Stabilire e mantenere contatti con gruppi di interesse speciale o altri forum specialistici sulla sicurezza e associazioni professionali. | D9: Managed | E9: La Direzione manitene contatti con gruppi di specialisti esterni all'azienda, sia come partner che per una semplice consultazione e approfondimento teorico e normativo.
B10: A.5.7 | C10: Raccolta e analisi delle informazioni relative alla minacce della sicurezza | D10: Managed | E10: Le informazioni relative alle minacce alla sicurezza delle informazioni sono raccolte e analizzate al fine di produrre informazioni sulle minacce
B11: A.5.8 | C11: Integrazione della sicurezza delle informazioni integrata nella gestione del progetto | D11: Managed | E11: La società garantisce la sicurezza delle informazioni relative alle attività di progettazione
B12: A.5.9 | C12: Sviluppare e mantenere un inventario delle informazioni e delle altre risorse associate, compresi i proprietari | D12: Managed | E12: La società garantisce la sicurezza delle informazioni relative alle attività di progettazione
B13: A.5.10 | C13: Devono essere identificate, documentate e attuate regole per l'uso accettabile e le procedure per la gestione delle risorse informatiche e di altri beni associati | D13: Managed | E13: E' stata definita un'apposita istruzione operativa per la gestione dei dispositivi portatili in luoghi diversi dalla sede operativa aziendale, ai fini della sicurezza delle informazioni.
B14: A.5.11 | C14: Se devono restituire tutti i beni dell'organizzazione in loro possesso al momento della modifica o della cessazione del loro impiego, contratto o accordo | D14: Managed | E14: La Direzione ha preso in carico la corretta gestione dell'applicazione delle procedure e delle istruzioni operative presso il personale aziendale e i collaboratori esterni.
B15: A.5.12 | C15: Classifica delle informazioni in base alle esigenze di sicurezza delle informazioni dell'organizzazione sulla riservatezza, integrità, disponibilità e requisiti delle parti interessate | D15: Managed | E15: La Direzione ha preso in carico la corretta gestione dell'applicazione delle procedure e delle istruzioni operative presso il personale aziendale e i collaboratori esterni.
... B40: A.5.37 | C40: Devono essere documentate e rese disponibili al personale che ne ha bisogno le procedure operativi per le strutture di elaborazione delle info. | D40: Managed | E40: Implementazione e definizione di sistema di gestione delle informazioni, completo di procedure, istruzioni operative e relativa modulistica. Le procedure sono disponibili al personale aziendale. Vengono gestite le informazioni inviate al personale esterno all'azienda
B41: A6 | C41: People controls
B42: A.6.1 | C42: Devono essere effettuati prima dell'ingresso nell'organizzazione tenendo in conto delle leggi, dei regolamenti e dell'etica applicabili e devono essere proporzionati ai requisiti aziendali, alla classificazione delle informazioni a cui si deve accedere e ai rischi | D42: Managed | E42: Prevista specifica procedura per la valutazione dei possibili candidati all'assunzione e dei possibili collaboratori/fornitori esterni
B43: A.6.2 | C43: Gli accordi contrattuali di lavoro devono indicare le responsabilità del personale e dell'organizzazione in materia di sicurezza informatica dell'organizzazione in materia di sicurezza informatica | D43: Managed | E43: L'azienda applica le condizioni previste da CCNL
B44: A.6.3 | C44: Il personale dell'organizzazione e le parti interessate devono ricevere un'adeguata sensibilizzazione, istruzione e formazione in materia di sicurezza delle informazioni | D44: Managed | E44: Esecuzione di formazione sulla norma e sulle procedure ed istruzioni interne al nuovo personale entrante, informazione al personale esterno sulle procedure e sulla gestione delle attività per la sicurezza delle informazioni
B45: A.6.4 | C45: Deve essere formalizzato e comunicato un processo disciplinare per intraprendere azioni contro il personale e le altre parti interessate che hanno commesso una violazione della politica di sicurezza delle informazioni | D45: Managed | E45: Si applica quanto definito a livello contrattuale
B46: A.6.5 | C46: Le responsabilità e i doveri in materia di sicurezza delle informazioni che rimangono validi anche dopo la cessazione o il cambiamento del rapporto di lavoro devono essere definiti, applicati e comunicati al personale interessato e alle altre parti coinvolte | D46: Managed | E46: Definite procedure di gestione della privacy e sulla cessazione del rapporto di lavoro
B47: A.6.6 | C47: Gli accordi di riservatezza o di non divulgazione che riflettono le esigenze dell'organizzazione in materia di protezione delle informazioni devono essere identificati, documentati, regolarmente rivisti e firmati dal personale e dalle altre parti interessate | D47: Managed | E47: Definiti accordi di riservatezza e di non divulgazione
B48: A.6.7 | C48: Le misure di sicurezza devono essere implementate quando il personale lavora a distanza per proteggere le informazioni a cui si accede, che vengono elaborate o archiviate al di fuori dei locali dell'organizzazione | D48: Managed | E48: E' stata definita un'apposita istruzione operativa per la gestione dei dispositivi portatili in luoghi diversi dalla sede operativa aziendale, ai fini della sicurezza delle informazioni
B49: A.6.8 | C49: L'organizzazione deve fornire un meccanismo che consenta al personale di segnalare tempestivamente eventi di sicurezza delle informazioni osservati o sospetti attraverso i canali appropria | D49: Managed | E49: In caso di anomalie e/o incidenti la segnalazione viene fatta direttamente dalla Direzione e al Responsabile di sistema
B50: A7 | C50: Physical controls
B51: A.7.1 | C51: I perimetri di sicurezza devono essere definiti e utilizzati per proteggere le aree che contengono informazioni e altri beni associati | D51: Managed | E51: L'azienda si avvale di server in cloud
B52: A.7.2 | C52: Le aree sicure devono essere protette da controlli e punti di accesso adeguati | D52: Managed | E52: Tutte le aree di lavoro sono delimitate con misure fisiche
B53: A.7.3 | C53: La sicurezza fisica di uffici, stanze e strutture deve essere progettata e implementata | D53: Managed | E53: Tutte le aree di lavoro sono delimitate con misure fisiche
B54: A.7.4 | C54: Locali dovranno essere costantemente monitorati per individuare eventuali | D54: Managed | E54: La sicurezza fisica degli uffici, dei locali e delle strutture è progettata e attuata
B55: A.7.5 | C55: La protezione contro le minacce fisiche e ambientali, come le catastrofi naturali e altre minacce fisiche intenzionali o non intenzionali alle infrastrutture, deve essere progettata e implementata | D55: Managed | E55: tutta la documentazione è in formato digitale, eseguiti back up periodici, definita una policy di restore dei dati
B56: A.7.6 | C56: Devono essere progettate e attuate misure di sicurezza per lavorare in aree sicure | D56: Managed | E56: Tutte le aree di lavoro sono delimitate con misure fisiche
B57: A.7.7 | C57: Devono essere definite e fatte rispettare regole chiare sulla scrivania per i documenti e i supporti di memorizzazione rimovibili e regole chiare sullo schermo per le strutture di elaborazione delle informazioni | D57: Managed | E57: Adottate Istruzioni per la gestione delle attrezzature informatiche con politica di schermo e scrivania puliti
B58: A.7.8 | C58: Le apparecchiature devono essere posizionate in modo sicuro e protetto | D58: Managed | E58: Tutte le aree di lavoro sono delimitate con misure fisiche; sono state predisposte istruzioni per la gestione degli accessi dall'esterno; sono state predisposte procedure e istruzioni per la gestione degli accessi non autorizzati e la gestione delle credenziali di accesso ai sistemi
B59: A.7.9 | C59: I beni fuori sede devono essere protetti | D59: Managed | E59: Applicazione di istruzioni di sicurezza per la gestione e il trasferimento all'esterno degli assett
B60: A.7.10 | C60: I supporti di memorizzazione devono essere gestiti durante il loro ciclo di vita di acquisizione, uso, trasporto e smaltimento in conformità allo schema di classificazione e ai requisiti di gestione dell'organizzazione | D60: Managed | E60: Definito apposito regolamento sulle modalità di gestione dei supporti rimovibili. Lo stesso è reso disponibile per la consultazione a tutti gli impiegati
B61: A.7.11 | C61: Utilità di supporto | D61: Managed | E61: Server online
B62: A.7.12 | C62: Sicurezza del cablaggio | D62: Managed | E62: Sono utilizzate le infrastrutture della compagnia telefonica ed elettrica a cui l'azienda ha deciso di affidarsi
... B64: A.7.14 | C64: Smaltimento sicuro o riutilizzo delle attrezzature | D64: Managed | E64: Applicate procedure in caso di dismissione di apparecchiature informatiche
B65: A8 | C65: Technological controls
...

Sheet Metrics
B2: Status | C2: Meaning | D2: Proportion of ISMS requirements | E2: Proportion of information security controls
B3: ? Unknown | C3: Has not even been checked yet | D3: =COUNTIF('Mandatory ISMS requirements'!$D$3:$D$60,$B3)/'Mandatory ISMS requirements'!$D$61 -> 0 | E3: =COUNTIF('Annex A controls'!$D$3:$D$99,$B3)/[0]!ControlTotal -> 0
B4: Nonexistent | C4: Complete lack of recognizable policy, procedure, control etc. | D4: =COUNTIF('Mandatory ISMS requirements'!$D$3:$D$60,$B4)/'Mandatory ISMS requirements'!$D$61 -> 0 | E4: =COUNTIF('Annex A controls'!$D$3:$D$99,$B4)/[0]!ControlTotal -> 0
B5: Initial | C5: Development has barely started and will require significant work to fulfill the requirements | D5: =COUNTIF('Mandatory ISMS requirements'!$D$3:$D$60,$B5)/'Mandatory ISMS requirements'!$D$61 -> 0 | E5: =COUNTIF('Annex A controls'!$D$3:$D$99,$B5)/[0]!ControlTotal -> 0
B6: Limited | C6: Progressing nicely but not yet complete | D6: =COUNTIF('Mandatory ISMS requirements'!$D$3:$D$60,$B6)/'Mandatory ISMS requirements'!$D$61 -> 0 | E6: =COUNTIF('Annex A controls'!$D$3:$D$99,$B6)/[0]!ControlTotal -> 0
B7: Defined | C7: Development is more or less complete although detail is lacking and/or it is not yet implemented, enforced and actively supported by top management | D7: =COUNTIF('Mandatory ISMS requirements'!$D$3:$D$60,$B7)/'Mandatory ISMS requirements'!$D$61 -> 0 | E7: =COUNTIF('Annex A controls'!$D$3:$D$99,$B7)/[0]!ControlTotal -> 0
B8: Managed | C8: Development is complete, the process/control has been implemented and recently started operating | D8: =COUNTIF('Mandatory ISMS requirements'!$D$3:$D$60,$B8)/'Mandatory ISMS requirements'!$D$61 -> 1 | E8: =COUNTIF('Annex A controls'!$D$3:$D$99,$B8)/[0]!ControlTotal -> 1
B9: Optimized | C9: The requirement is fully satisfied, is operating fully as expected, is being actively monitored and improved, and there is substantial evidence to prove all that to the auditors | D9: =COUNTIF('Mandatory ISMS requirements'!$D$3:$D$60,$B9)/'Mandatory ISMS requirements'!$D$61 -> 0 | E9: =COUNTIF('Annex A controls'!$D$3:$D$99,$B9)/[0]!ControlTotal -> 0
B10: Not applicable | C10: ALL requirements in the main body of ISO/IEC 27001 are mandatory IF your ISMS is to be certified. Otherwise, managemnent can ignore them. | D10: =COUNTIF('Mandatory ISMS requirements'!$D$3:$D$60,$B10)/'Mandatory ISMS requirements'!$D$61 -> 0 | E10: =COUNTIF('Annex A controls'!$D$3:$D$99,$B10)/[0]!ControlTotal -> 0
C11: Total | D11: =SUM(D3:D10) -> 1 | E11: =SUM(E3:E10) -> 1
